<robot name="bravo7">
    <link name="base_link"/>
    <material name="bravo_black">
    <color rgba="0.3 0.3 0.3 1"/>
    </material>
    <joint name="bravo_joint" type="fixed">
        <origin rpy="0 0 0" xyz="0 0 0"/>
        <parent link="base_link"/>
        <child link="bravo_base_link"/>
    </joint>
    <link name="bravo_base_link"/>


    <link name="bravo_rs2_266_link">
        <visual>
            <geometry>
                <mesh filename="/home/carlos18/optimization_ws/src/bravo_description/meshes/RS2-266.stl"/>
            </geometry>
            <material name="bravo_black"/>
        </visual>
    </link>

    <joint name="bravo_rs2_266_joint" type="fixed">
        <parent link="bravo_base_link"/>
        <child link="bravo_rs2_266_link"/>
        <origin rpy="0 0 0"/>
    </joint>

    <link name="bravo_rs2_217_link">
        <visual>
            <geometry>
                <mesh filename="/home/carlos18/optimization_ws/src/bravo_description/meshes/RS2-217.stl"/>
            </geometry>
            <material name="bravo_black"/>
        </visual>
    </link>

    <joint name="bravo_axis_g" type="revolute">
        <parent link="bravo_rs2_266_link"/>
        <child link="bravo_rs2_217_link"/>
        <origin rpy="0 0 0" xyz="0.0665 0 0.078"/>
        <axis xyz="0 0 -1"/>
        <safety_controller k_position="100.0" k_velocity="40.0" soft_lower_limit="-2.8973" soft_upper_limit="2.8973"/>
        <dynamics damping="10.0"/>
        <limit effort="87" lower="-2.8973" upper="2.8973" velocity="2.1750"/>
    </joint>

    <link name="bravo_rs2_250_212_214_link">
        <visual>
            <geometry>
                <mesh filename="/home/carlos18/optimization_ws/src/bravo_description/meshes/RS2-250-212-214.stl"/>
            </geometry>
            <material name="bravo_black"/>
        </visual>
    </link>

    <joint name="bravo_axis_f" type="revolute">
        <parent link="bravo_rs2_217_link"/>
        <child link="bravo_rs2_250_212_214_link"/>
        <origin rpy="0 0 0" xyz="-0.046 0 0.0674"/>
        <axis xyz="0 1 0"/>
        <safety_controller k_position="100.0" k_velocity="40.0" soft_lower_limit="-2.8973" soft_upper_limit="2.8973"/>
        <dynamics damping="10.0"/>
        <limit effort="87" lower="-2.8973" upper="2.8973" velocity="2.1750"/>
    </joint>

    <link name="bravo_rs2_268_link">
        <visual>
            <geometry>
                <mesh filename="/home/carlos18/optimization_ws/src/bravo_description/meshes/RS2-268.stl"/>
            </geometry>
            <material name="bravo_black"/>
        </visual>
    </link>

    <joint name="bravo_axis_e" type="revolute">
        <parent link="bravo_rs2_250_212_214_link"/>
        <child link="bravo_rs2_268_link"/>
        <origin rpy="0 0 0" xyz="-0.0052 0 -0.29055"/>
        <axis xyz="0 1 0"/>
        <safety_controller k_position="100.0" k_velocity="40.0" soft_lower_limit="-2.8973" soft_upper_limit="2.8973"/>
        <dynamics damping="10.0"/>
        <limit effort="87" lower="-2.8973" upper="2.8973" velocity="2.1750"/>
    </joint>


    <link name="bravo_rs2_214_link">
        <visual>
            <geometry>
                <mesh filename="/home/carlos18/optimization_ws/src/bravo_description/meshes/RS2-214.stl"/>
            </geometry>
            <material name="bravo_black"/>
        </visual>
    </link>

    <joint name="bravo_axis_d" type="revolute">
        <parent link="bravo_rs2_268_link"/>
        <child link="bravo_rs2_214_link"/>
        <origin rpy="0 0 0" xyz="0.0408 0 0.09695"/>
        <axis xyz="0 0 -1"/>
        <safety_controller k_position="100.0" k_velocity="40.0" soft_lower_limit="-2.8973" soft_upper_limit="2.8973"/>
        <dynamics damping="10.0"/>
        <limit effort="87" lower="-2.8973" upper="2.8973" velocity="2.1750"/>
    </joint>

    <link name="bravo_rs2_161_link">
        <visual>
            <geometry>
                <mesh filename="/home/carlos18/optimization_ws/src/bravo_description/meshes/RS2-161.stl"/>
            </geometry>
            <material name="bravo_black"/>
        </visual>
    </link>

    <joint name="bravo_axis_c" type="revolute">
        <parent link="bravo_rs2_214_link"/>
        <child link="bravo_rs2_161_link"/>
        <origin rpy="0 0 0" xyz="-0.0408 0 0.063"/>
        <axis xyz="0 1 0"/>
        <safety_controller k_position="100.0" k_velocity="40.0" soft_lower_limit="-2.8973" soft_upper_limit="2.8973"/>
        <dynamics damping="10.0"/>
        <limit effort="87" lower="-2.8973" upper="2.8973" velocity="2.1750"/>
    </joint>



    <link name="bravo_rs2_180_link">
        <visual>
            <geometry>
                <mesh filename="/home/carlos18/optimization_ws/src/bravo_description/meshes/RS2-180.stl"/>
            </geometry>
            <material name="bravo_black"/>
        </visual>
    </link>

    <link name="FT_link">
        <visual>
            <geometry>
                <cylinder length="0.06" radius="0.04"/>
            </geometry>
            <material name="bravo_black"/>
        </visual>
    </link>

    <joint name="FT_fixed_1" type="fixed">
    <origin rpy="0 0 0" xyz=" 0 0 -0.03"/>
    <parent link="bravo_rs2_180_link"/>
    <child link="FT_link"/>
    </joint>

    <joint name="bravo_axis_b" type="revolute">
        <parent link="bravo_rs2_161_link"/>
        <child link="bravo_rs2_180_link"/>
        <origin rpy="0 3.14159 0" xyz="-0.0408 0 -0.14863"/>
        <axis xyz="0 0 -1"/>
        <safety_controller k_position="100.0" k_velocity="40.0" soft_lower_limit="-2.8973" soft_upper_limit="2.8973"/>
        <dynamics damping="10.0"/>
        <limit effort="87" lower="-2.8973" upper="2.8973" velocity="2.1750"/>
    </joint>

    <!-- add end_effector frame -->
  <link name="tip">
  </link>

  <joint name="arm_to_tip" type="fixed">
    <parent link="bravo_jaws_base_link"/>
    <child link="tip"/>
    <origin xyz="0 0 0.10" rpy="0 0 0"/>
  </joint>
  
</robot>
