<robot name="bravo7">
    <link name="base_link" />
    <material name="bravo_black">
        <color rgba="0.3 0.3 0.3 1" />
    </material>
    <joint name="bravo_joint" type="fixed">
        <origin rpy="0 0 0" xyz="0 0 0" />
        <parent link="base_link" />
        <child link="bravo_base_link" />
    </joint>
    <link name="bravo_base_link" />
    <link name="bravo_rs2_266_link">
        <visual>
            <geometry>
                <mesh filename="package://bravo_description/meshes/RS2-266.stl" />
            </geometry>
            <material name="bravo_black" />
        </visual>
    </link>
    <joint name="bravo_rs2_266_joint" type="fixed">
        <parent link="bravo_base_link" />
        <child link="bravo_rs2_266_link" />
        <origin rpy="0 0 0" />
    </joint>
    <link name="bravo_rs2_217_link">
        <visual>
            <geometry>
                <mesh filename="package://bravo_description/meshes/RS2-217.stl" />
            </geometry>
            <material name="bravo_black" />
        </visual>
    </link>
    <joint name="bravo_axis_g" type="revolute">
        <parent link="bravo_rs2_266_link" />
        <child link="bravo_rs2_217_link" />
        <origin rpy="0 0 0" xyz="0.0665 0 0.078" />
        <axis xyz="0 0 -1" />
        <limit effort="9.0" lower="0.0" upper="6.3" velocity="0.5" />
    </joint>
    <link name="bravo_rs2_250_212_214_link">
        <visual>
            <geometry>
                <mesh filename="package://bravo_description/meshes/RS2-250-212-214.stl" />
            </geometry>
            <material name="bravo_black" />
        </visual>
    </link>
    <joint name="bravo_axis_f" type="revolute">
        <parent link="bravo_rs2_217_link" />
        <child link="bravo_rs2_250_212_214_link" />
        <origin rpy="0 0 0" xyz="-0.046 0 0.0674" />
        <axis xyz="0 1 0" />
        <limit effort="9.0" lower="0.0" upper="3.5" velocity="0.5" />
    </joint>
    <link name="bravo_rs2_268_link">
        <visual>
            <geometry>
                <mesh filename="package://bravo_description/meshes/RS2-268.stl" />
            </geometry>
            <material name="bravo_black" />
        </visual>
    </link>
    <joint name="bravo_axis_e" type="revolute">
        <parent link="bravo_rs2_250_212_214_link" />
        <child link="bravo_rs2_268_link" />
        <origin rpy="0 0 0" xyz="-0.0052 0 -0.29055" />
        <axis xyz="0 1 0" />
        <limit effort="9.0" lower="0.0" upper="3.5" velocity="0.5" />
    </joint>
    <link name="bravo_rs2_214_link">
        <visual>
            <geometry>
                <mesh filename="package://bravo_description/meshes/RS2-214.stl" />
            </geometry>
            <material name="bravo_black" />
        </visual>
    </link>
    <joint name="bravo_axis_d" type="revolute">
        <parent link="bravo_rs2_268_link" />
        <child link="bravo_rs2_214_link" />
        <origin rpy="0 0 3.14159" xyz="0.0408 0 0.09695" />
        <axis xyz="0 0 -1" />
        <limit effort="9.0" lower="0.0" upper="6.3" velocity="0.5" />
    </joint>
    <link name="bravo_rs2_161_link">
        <visual>
            <geometry>
                <mesh filename="package://bravo_description/meshes/RS2-161.stl" />
            </geometry>
            <material name="bravo_black" />
        </visual>
    </link>
    <joint name="bravo_axis_c" type="revolute">
        <parent link="bravo_rs2_214_link" />
        <child link="bravo_rs2_161_link" />
        <origin rpy="0 0 0" xyz="-0.0408 0 0.063" />
        <axis xyz="0 1 0" />
        <limit effort="9.0" lower="0.0" upper="3.5" velocity="0.5" />
    </joint>
    <link name="bravo_rs2_180_link">
        <visual>
            <geometry>
                <mesh filename="package://bravo_description/meshes/RS2-180.stl" />
            </geometry>
            <material name="bravo_black" />
        </visual>
    </link>
    <joint name="bravo_axis_b" type="revolute">
        <parent link="bravo_rs2_161_link" />
        <child link="bravo_rs2_180_link" />
        <origin rpy="0 3.14159 0" xyz="-0.0408 0 -0.08863" />
        <axis xyz="0 0 -1" />
        <limit effort="9.0" lower="0.0" upper="6.3" velocity="0.5" />
    </joint>
    <joint name="bravo_jaws_joint" type="fixed">
        <origin rpy="0 0 0" xyz=" 0 0 0.124" />
        <parent link="bravo_rs2_180_link" />
        <child link="bravo_jaws_base_link" />
    </joint>
    <material name="bravo_jaws_black">
        <color rgba="0.3 0.3 0.3 1" />
    </material>
    <link name="bravo_jaws_base_link">
        <visual>
            <geometry>
                <mesh filename="package://bravo_description/meshes/end_effectors/RS2-257.stl" />
            </geometry>
            <material name="bravo_jaws_black" />
        </visual>
    </link>
    <link name="bravo_push_rod" />
    <joint name="bravo_axis_a" type="prismatic">
        <origin rpy="0 0 0" xyz="0 0 0.009" />
        <parent link="bravo_jaws_base_link" />
        <child link="bravo_push_rod" />
        <axis xyz="0 0 1" />
        <limit effort="10" lower="0" upper="0.035" velocity="10" />
    </joint>
    <link name="bravo_rs2_255_link">
        <visual>
            <geometry>
                <mesh filename="package://bravo_description/meshes/end_effectors/RS2-255.stl" />
            </geometry>
            <material name="bravo_jaws_black" />
            <origin rpy="0 0 0" xyz="0 0 0" />
        </visual>
    </link>
    <joint name="bravo_rs2_255_joint" type="revolute">
        <origin rpy="0 0 0" xyz="0 0.033 0.0097" />
        <parent link="bravo_jaws_base_link" />
        <child link="bravo_rs2_255_link" />
        <axis xyz="-1 0 0" />
        <limit effort="10" lower="0" upper="0.5" velocity="10" />
        <mimic joint="bravo_axis_a" multiplier="15" offset="0" />
    </joint>
    <link name="bravo_rs2_255_jaw_inside_link">
        <visual>
            <geometry>
                <mesh filename="package://bravo_description/meshes/end_effectors/RS2-255-Jaw-Inside.stl" />
            </geometry>
            <material name="bravo_jaws_black" />
            <origin rpy="0 0 0" xyz="0 0 0" />
        </visual>
    </link>
    <joint name="bravo_rs2_255_jaw_inside_joint" type="revolute">
        <origin rpy="0 0 0" xyz="0 -0.033 0.0097" />
        <parent link="bravo_jaws_base_link" />
        <child link="bravo_rs2_255_jaw_inside_link" />
        <axis xyz="1 0 0" />
        <limit effort="10" lower="0" upper="0.5" velocity="10" />
        <mimic joint="bravo_axis_a" multiplier="15" offset="0" />
    </joint>
    <!-- add end_effector frame -->
    <link name="tip" />
    <joint name="arm_to_tip" type="fixed">
        <parent link="bravo_jaws_base_link" />
        <child link="tip" />
        <origin xyz="0 0 0.10" rpy="0 0 0" />
    </joint>
    
<transmission name="trans_bravo_axis_g">
        <type>transmission_interface/SimpleTransmission</type>
        <joint name="bravo_axis_g">
            <hardwareInterface>hardware_interface/EffortJointInterface</hardwareInterface>
        </joint>
        <actuator name="bravo_axis_g_motor">
            <hardwareInterface>hardware_interface/EffortJointInterface</hardwareInterface>
            <mechanicalReduction>1</mechanicalReduction>
        </actuator>
    </transmission>
    <transmission name="trans_bravo_axis_f">
        <type>transmission_interface/SimpleTransmission</type>
        <joint name="bravo_axis_f">
            <hardwareInterface>hardware_interface/EffortJointInterface</hardwareInterface>
        </joint>
        <actuator name="bravo_axis_f_motor">
            <hardwareInterface>hardware_interface/EffortJointInterface</hardwareInterface>
            <mechanicalReduction>1</mechanicalReduction>
        </actuator>
    </transmission>
    <transmission name="trans_bravo_axis_e">
        <type>transmission_interface/SimpleTransmission</type>
        <joint name="bravo_axis_e">
            <hardwareInterface>hardware_interface/EffortJointInterface</hardwareInterface>
        </joint>
        <actuator name="bravo_axis_e_motor">
            <hardwareInterface>hardware_interface/EffortJointInterface</hardwareInterface>
            <mechanicalReduction>1</mechanicalReduction>
        </actuator>
    </transmission>
    <transmission name="trans_bravo_axis_d">
        <type>transmission_interface/SimpleTransmission</type>
        <joint name="bravo_axis_d">
            <hardwareInterface>hardware_interface/EffortJointInterface</hardwareInterface>
        </joint>
        <actuator name="bravo_axis_d_motor">
            <hardwareInterface>hardware_interface/EffortJointInterface</hardwareInterface>
            <mechanicalReduction>1</mechanicalReduction>
        </actuator>
    </transmission>
    <transmission name="trans_bravo_axis_c">
        <type>transmission_interface/SimpleTransmission</type>
        <joint name="bravo_axis_c">
            <hardwareInterface>hardware_interface/EffortJointInterface</hardwareInterface>
        </joint>
        <actuator name="bravo_axis_c_motor">
            <hardwareInterface>hardware_interface/EffortJointInterface</hardwareInterface>
            <mechanicalReduction>1</mechanicalReduction>
        </actuator>
    </transmission>
    <transmission name="trans_bravo_axis_b">
        <type>transmission_interface/SimpleTransmission</type>
        <joint name="bravo_axis_b">
            <hardwareInterface>hardware_interface/EffortJointInterface</hardwareInterface>
        </joint>
        <actuator name="bravo_axis_b_motor">
            <hardwareInterface>hardware_interface/EffortJointInterface</hardwareInterface>
            <mechanicalReduction>1</mechanicalReduction>
        </actuator>
    </transmission>
    <transmission name="trans_bravo_axis_a">
        <type>transmission_interface/SimpleTransmission</type>
        <joint name="bravo_axis_a">
            <hardwareInterface>hardware_interface/EffortJointInterface</hardwareInterface>
        </joint>
        <actuator name="bravo_axis_a_motor">
            <hardwareInterface>hardware_interface/EffortJointInterface</hardwareInterface>
            <mechanicalReduction>1</mechanicalReduction>
        </actuator>
    </transmission>
    <transmission name="trans_bravo_rs2_255_joint">
        <type>transmission_interface/SimpleTransmission</type>
        <joint name="bravo_rs2_255_joint">
            <hardwareInterface>hardware_interface/EffortJointInterface</hardwareInterface>
        </joint>
        <actuator name="bravo_rs2_255_joint_motor">
            <hardwareInterface>hardware_interface/EffortJointInterface</hardwareInterface>
            <mechanicalReduction>1</mechanicalReduction>
        </actuator>
    </transmission>
    <transmission name="trans_bravo_rs2_255_jaw_inside_joint">
        <type>transmission_interface/SimpleTransmission</type>
        <joint name="bravo_rs2_255_jaw_inside_joint">
            <hardwareInterface>hardware_interface/EffortJointInterface</hardwareInterface>
        </joint>
        <actuator name="bravo_rs2_255_jaw_inside_joint_motor">
            <hardwareInterface>hardware_interface/EffortJointInterface</hardwareInterface>
            <mechanicalReduction>1</mechanicalReduction>
        </actuator>
    </transmission>
    <gazebo>
        <plugin name="gazebo_ros_control" filename="libgazebo_ros_control.so">
            <robotNamespace>/</robotNamespace>
        </plugin>
    </gazebo>
</robot>